Workbook

Sheet Energy Target
A1: Daily Energy Target (Mifflin-St Jeor)
A2: Yellow cells = inputs. Maathina, ellaa numbers-um auto-va update aagum.
A4: Item | B4: Value | C4: Note
A5: Age (years) | B5: 40 | C5: User profile-la irundhu
A6: Height (cm) | B6: 155 | C6: "5.1" ah 5 ft 1 in ≈ 155 cm nu eduthukitten (assumption)
A7: Current weight (kg) | B7: 95 | C7: User profile-la irundhu
A8: Goal weight (kg) | B8: 64 | C8: User profile-la irundhu
A9: Activity factor | B9: 1.2 | C9: Sedentary = 1.2 (Lightly 1.375, Moderately 1.55, Very 1.725)
A10: Calorie deficit (kcal/day) | B10: 470 | C10: Moderate deficit, 300–500 range-kulla
A11: Protein (g per kg goal weight) | B11: 1 | C11: Recommended range 1.0–1.2
A12: Minimum calorie floor (women) | B12: 1200 | C12: Idhukku keezha poga koodaadhu
A13: BMR (kcal/day) | B13: =ROUND(10*B7+6.25*B6-5*B5-161,-1) -> 1560 | C13: 10×weight + 6.25×height − 5×age − 161
A14: TDEE / maintenance (kcal/day) | B14: =ROUND(B13*B9,-1) -> 1870 | C14: BMR × activity factor
A15: Daily calorie target (kcal/day) | B15: =MAX(ROUND(B14-B10,-2),B12) -> 1400 | C15: TDEE − deficit, rounded, floor-ku mela
A16: Daily protein target (g) | B16: =ROUND(B8*B11,0) -> 64 | C16: Goal weight × g/kg
A17: Expected loss (kg/week) | B17: =ROUND((B14-B15)*7/7700,2) -> 0.43 | C17: 1 kg fat ≈ 7,700 kcal
A18: BMI (current) | B18: =ROUND(B7/(B6/100)^2,1) -> 39.5 | C18: Weight ÷ height² (m)

Sheet Meal Plan
A1: 7-Day Tamil Nadu Lacto-Vegetarian Meal Plan (~1,400 kcal)
A2: kcal & protein = approximate estimates. Oil ~1 tsp per meal (3–4 tsp/day). Day total rows auto-sum.
A4: Day | B4: Meal | C4: Dish | D4: Portion (household measure) | E4: Approx. quantity (g/ml) | F4: Approx. kcal | G4: Protein (g)
A5: Day 1 (Mon) | B5: Breakfast | C5: Ragi dosai + thakkali chutney + sambar + filter coffee | D5: 2 medium dosai (½ tsp oil each), 2 tbsp chutney, 1 katori sambar, 1 tumbler coffee | E5: 120 g dosai, 30 g chutney, 150 ml sambar, 100 ml coffee | F5: 390 | G5: 15
A6: Day 1 (Mon) | B6: Lunch (tiffin) | C6: Mulai keerai kootu + red rice + beans poriyal + thayir | D6: 1 cup kootu, ½ cup sivappu arisi sadam, ½ cup poriyal, 1 katori thayir | E6: 200 g kootu, 75 g rice, 75 g poriyal, 150 g curd | F6: 420 | G6: 18
A7: Day 1 (Mon) | B7: Evening Snack | C7: Kondakadalai sundal + koyyapazham | D7: ½ cup sundal, 1 medium guava | E7: 80 g sundal, 150 g guava | F7: 210 | G7: 9
A8: Day 1 (Mon) | B8: Dinner | C8: Chapathi + paneer pattani kurma + vellarikkai salad | D8: 2 chapathi (ghee illama), ½ cup kurma, 1 small plate salad | E8: 60 g atta, 60 g paneer in 150 ml kurma, 80 g cucumber | F8: 440 | G8: 20
A9: Day 1 (Mon) | B9: Day total | F9: =SUM(F5:F8) -> 1460 | G9: =SUM(G5:G8) -> 62
A10: Day 2 (Tue) | B10: Breakfast | C10: Pesarattu + inji chutney + filter coffee | D10: 2 medium pesarattu, 2 tbsp chutney, 1 tumbler coffee | E10: 160 g batter, 30 g chutney, 100 ml coffee | F10: 350 | G10: 18
A11: Day 2 (Tue) | B11: Lunch (tiffin) | C11: Thinai sambar sadam + vellarikkai thayir pachadi + neer mor | D11: 1½ cups sambar sadam, ½ cup pachadi, 1 glass mor | E11: 300 g, 100 g, 200 ml | F11: 490 | G11: 19
A12: Day 2 (Tue) | B12: Evening Snack | C12: Pachai payaru sundal + orange | D12: ¾ cup sundal, 1 orange | E12: 120 g, 130 g | F12: 190 | G12: 10
A13: Day 2 (Tue) | B13: Dinner | C13: Murungai keerai adai + avial | D13: 2 medium adai (1 tsp oil total), ½ cup avial | E13: 180 g batter, 100 g avial | F13: 410 | G13: 15
A14: Day 2 (Tue) | B14: Day total | F14: =SUM(F10:F13) -> 1440 | G14: =SUM(G10:G13) -> 62
A15: Day 3 (Wed) | B15: Breakfast | C15: Idli + sambar + pudina chutney + filter coffee | D15: 3 medium idli, 1 katori sambar, 2 tbsp chutney, 1 tumbler coffee | E15: 150 g idli, 150 ml sambar, 30 g chutney, 100 ml coffee | F15: 380 | G15: 16
A16: Day 3 (Wed) | B16: Lunch (tiffin) | C16: Kambu sadam + kathirikai paruppu kootu + carrot poriyal + thayir | D16: ½ cup kambu sadam, 1 cup kootu, ½ cup poriyal, ½ katori thayir | E16: 80 g, 200 g, 75 g, 100 g | F16: 390 | G16: 15
A17: Day 3 (Wed) | B17: Evening Snack | C17: Verkadalai (boiled peanut) sundal + papaya | D17: ⅓ cup sundal, 1 cup papaya pieces | E17: 50 g, 150 g | F17: 200 | G17: 8
A18: Day 3 (Wed) | B18: Dinner | C18: Chapathi + keerai paneer (palak paneer) + vengaya salad | D18: 2 chapathi, ½ cup keerai paneer, small plate salad | E18: 60 g atta, 75 g paneer + 100 g palak, 60 g salad | F18: 450 | G18: 22
A19: Day 3 (Wed) | B19: Day total | F19: =SUM(F15:F18) -> 1420 | G19: =SUM(G15:G18) -> 61
A20: Day 4 (Thu) | B20: Breakfast | C20: Samai pongal + thakkali chutney + sambar + filter coffee | D20: ¾ cup pongal (½ tsp ghee), 2 tbsp chutney, ½ katori sambar, 1 tumbler coffee | E20: 180 g pongal, 30 g chutney, 75 ml sambar, 100 ml coffee | F20: 390 | G20: 15
A21: Day 4 (Thu) | B21: Lunch (tiffin) | C21: Thakkali paruppu + red rice + kovakkai poriyal + thayir | D21: 1 big katori paruppu, ½ cup sadam, ½ cup poriyal, 1 katori thayir | E21: 200 ml, 75 g, 75 g, 150 g | F21: 430 | G21: 18
A22: Day 4 (Thu) | B22: Evening Snack | C22: Karamani sundal + apple | D22: ½ cup sundal, 1 small apple | E22: 80 g, 130 g | F22: 190 | G22: 7
A23: Day 4 (Thu) | B23: Dinner | C23: Ragi idiyappam + paneer kaai kurma + murungai keerai poriyal | D23: 2 idiyappam, 1 katori kurma, ¼ cup poriyal | E23: 80 g, 75 g paneer in 150 ml kurma, 50 g poriyal | F23: 410 | G23: 20
A24: Day 4 (Thu) | B24: Day total | F24: =SUM(F20:F23) -> 1420 | G24: =SUM(G20:G23) -> 60
A25: Day 5 (Fri) | B25: Breakfast | C25: Kuzhi paniyaram (veg) + sambar + filter coffee | D25: 5 small paniyaram (1 tsp oil), 1 katori sambar, 1 tumbler coffee | E25: 125 g, 150 ml, 100 ml | F25: 360 | G25: 14
A26: Day 5 (Fri) | B26: Lunch (tiffin) | C26: Varagu thayir sadam with vellarikkai + pasi paruppu kosambari + beetroot-carrot salad | D26: 1½ cups thayir sadam, ½ cup kosambari, ½ cup salad | E26: 300 g (200 g curd ulla), 60 g, 80 g | F26: 430 | G26: 17
A27: Day 5 (Fri) | B27: Evening Snack | C27: Mulai kattiya payaru salad + pottukadalai + papaya | D27: 1 cup sprouts, 1 tbsp pottukadalai, 1 cup papaya | E27: 100 g, 15 g, 150 g | F27: 210 | G27: 10
A28: Day 5 (Fri) | B28: Dinner | C28: Chapathi + pasi payaru kuzhambu + vengaya-vellarikkai salad | D28: 2 chapathi, 1 big katori kuzhambu, small plate salad | E28: 60 g atta, 200 ml, 60 g | F28: 440 | G28: 20
A29: Day 5 (Fri) | B29: Day total | F29: =SUM(F25:F28) -> 1440 | G29: =SUM(G25:G28) -> 61
A30: Day 6 (Sat) | B30: Breakfast | C30: Thinai vegetable upma + thengai-pottukadalai chutney + filter coffee | D30: ¾ cup upma, 2 tbsp chutney, 1 tumbler coffee | E30: 150 g, 30 g, 100 ml | F30: 330 | G30: 11
A31: Day 6 (Sat) | B31: Lunch (home) | C31: Murungakkai sambar + red rice + avial + rasam + thayir | D31: 1 big katori sambar, ½ cup sadam, ½ cup avial, 1 small katori rasam, ½ katori thayir | E31: 200 ml, 75 g, 100 g, 100 ml, 100 g | F31: 450 | G31: 17
A32: Day 6 (Sat) | B32: Evening Snack | C32: Verkadalai sundal + masala mor | D32: ⅓ cup sundal, 1 glass mor | E32: 50 g, 200 ml | F32: 180 | G32: 9
A33: Day 6 (Sat) | B33: Dinner | C33: Godhumai dosai + Chettinad paneer masala | D33: 2 dosai (1 tsp oil total), ½ cup masala | E33: 70 g atta, 75 g paneer in 120 ml gravy | F33: 470 | G33: 21
A34: Day 6 (Sat) | B34: Day total | F34: =SUM(F30:F33) -> 1430 | G34: =SUM(G30:G33) -> 58
A35: Day 7 (Sun) | B35: Breakfast | C35: Idli + medu vadai (WEEKLY TREAT, 1 small) + sambar + thengai chutney + filter coffee | D35: 3 medium idli, 1 small vadai, 1 katori sambar, 2 tbsp chutney, 1 tumbler coffee | E35: 150 g, 40 g, 150 ml, 30 g, 100 ml | F35: 520 | G35: 20
A36: Day 7 (Sun) | B36: Lunch (home) | C36: Mor kuzhambu + red rice + beans paruppu usili + pasalai keerai poriyal + rasam | D36: 1 katori kuzhambu, ½ cup sadam, ½ cup usili, ¼ cup poriyal, 1 small katori rasam | E36: 150 ml, 75 g, 100 g, 50 g, 100 ml | F36: 440 | G36: 16
A37: Day 7 (Sun) | B37: Evening Snack | C37: Pachai payaru sundal + orange | D37: ¾ cup sundal, 1 orange | E37: 120 g, 130 g | F37: 190 | G37: 10
A38: Day 7 (Sun) | B38: Dinner | C38: Pasi paruppu vegetable kichadi + vellarikkai raita | D38: 1 cup kichadi, ½ cup raita | E38: 200 g, 100 g | F38: 310 | G38: 13
A39: Day 7 (Sun) | B39: Day total | F39: =SUM(F35:F38) -> 1460 | G39: =SUM(G35:G38) -> 59
E40: Weekly average / day | F40: =ROUND(AVERAGE(F9,F14,F19,F24,F29,F34,F39),0) -> 1439 | G40: =ROUND(AVERAGE(G9,G14,G19,G24,G29,G34,G39),0) -> 60
E41: Target (from Energy Target) | F41: ='Energy Target'!B15 -> 1400 | G41: ='Energy Target'!B16 -> 64
...

Sheet Weekly Snapshot
A1: Weekly Snapshot
A2: Totals Meal Plan sheet-la irundhu link aagudhu (green).
A4: Day | B4: Total kcal | C4: Total protein (g) | D4: vs kcal target | E4: Millet/whole-grain used | F4: Greens/vegetables used
A5: Day 1 (Mon) | B5: ='Meal Plan'!F9 -> 1460 | C5: ='Meal Plan'!G9 -> 62 | D5: =B5-'Energy Target'!$B$15 -> 60 | E5: Ragi, red rice, wheat | F5: Mulai keerai, beans, cucumber, peas
A6: Day 2 (Tue) | B6: ='Meal Plan'!F14 -> 1440 | C6: ='Meal Plan'!G14 -> 62 | D6: =B6-'Energy Target'!$B$15 -> 40 | E6: Thinai | F6: Murungai keerai, avial kaai, cucumber
A7: Day 3 (Wed) | B7: ='Meal Plan'!F19 -> 1420 | C7: ='Meal Plan'!G19 -> 61 | D7: =B7-'Energy Target'!$B$15 -> 20 | E7: Kambu, wheat | F7: Palak, kathirikai, carrot
A8: Day 4 (Thu) | B8: ='Meal Plan'!F24 -> 1420 | C8: ='Meal Plan'!G24 -> 60 | D8: =B8-'Energy Target'!$B$15 -> 20 | E8: Samai, ragi, red rice | F8: Murungai keerai, kovakkai, tomato
A9: Day 5 (Fri) | B9: ='Meal Plan'!F29 -> 1440 | C9: ='Meal Plan'!G29 -> 61 | D9: =B9-'Energy Target'!$B$15 -> 40 | E9: Varagu, wheat | F9: Beetroot, carrot, cucumber
A10: Day 6 (Sat) | B10: ='Meal Plan'!F34 -> 1430 | C10: ='Meal Plan'!G34 -> 58 | D10: =B10-'Energy Target'!$B$15 -> 30 | E10: Thinai, red rice | F10: Murungakkai, avial kaai
A11: Day 7 (Sun) | B11: ='Meal Plan'!F39 -> 1460 | C11: ='Meal Plan'!G39 -> 59 | D11: =B11-'Energy Target'!$B$15 -> 60 | E11: Red rice | F11: Pasalai keerai, beans, cucumber
A12: Average | B12: =ROUND(AVERAGE(B5:B11),0) -> 1439 | C12: =ROUND(AVERAGE(C5:C11),0) -> 60
A14: Note: Protein sarasari ~60 g, target 65 g-ku konjam kammi. Daily 1 extra katori thayir illa 1 glass mor serthaa (~50 kcal) target reach aagum.

Sheet Grocery List
A1: Grocery List for the Week (1 person)
A2: Bought? column-la ✓ podunga.
A4: Category | B4: Item | C4: Approx. quantity | D4: Bought?
A5: Grains & Millets | B5: Ragi flour | C5: 250 g
A6: Grains & Millets | B6: Thinai (foxtail millet) | C6: 400 g
A7: Grains & Millets | B7: Kambu (bajra) | C7: 150 g
A8: Grains & Millets | B8: Samai (little millet) | C8: 200 g
A9: Grains & Millets | B9: Varagu (kodo millet) | C9: 200 g
A10: Grains & Millets | B10: Sivappu arisi (red rice) | C10: 500 g
A11: Grains & Millets | B11: Idli/dosai batter (or idli arisi 400 g + ulundhu 100 g) | C11: 1 kg
A12: Grains & Millets | B12: Wheat atta | C12: 500 g
A13: Grains & Millets | B13: Puzhungal arisi (for adai) | C13: 100 g
A14: Pulses & Dals | B14: Thuvaram paruppu | C14: 300 g
A15: Pulses & Dals | B15: Pasi paruppu | C15: 300 g
A16: Pulses & Dals | B16: Pachai payaru (whole moong) | C16: 500 g
... A56: Spices & Others | B56: Uppu | C56: As needed

Sheet Swaps & Tips
A1: Smart Swaps, Prep Ahead Tips & Daily Habits
A3: Smart Swaps
A4: 1 | B4: Thinai ↔ samai ↔ varagu: ellaam ore maadhiri samaikkalaam, ethu kidaikkudho adha use pannunga.
A5: 2 | B5: Paneer ↔ hung curd (thick thayir): gravy-la kadaisila serunga, kodhikka vidaadheenga.
A6: 3 | B6: Murungai keerai ↔ mulai keerai ↔ siru keerai: adai, poriyal, kootu ellaathukkum maathikkalaam.
A7: 4 | B7: Kondakadalai ↔ karamani ↔ mochai: sundal-ku same alavu.
A8: 5 | B8: Red rice ↔ kaikuthal arisi ↔ ½ ponni + ½ thinai: portion maathaama ½ cup thaan.
A9: 6 | B9: Papaya ↔ guava ↔ orange: season-la ethu cheap-a irukko adhu.
A11: Prep Ahead Tips
A12: 1 | B12: Sunday-yum Wednesday-yum idli/dosai batter araichi vachukonga. Ragi dosai-ku adhula ragi flour kalandhukalaam.
A13: 2 | B13: Raathiri thoonga pora munnaadi adutha naal sundal-ku kondakadalai/karamani/pachai payaru oora vaiyunga. Pachai payaru-va 2 naal munnaadi oora vachaa sprouts ready aagidum.
A14: 3 | B14: Sambar-um paruppu-vum 2 meal-ku sethu vaiyunga (breakfast sambar-a lunch-kum, kuzhambu-va dinner-kum). Fridge-la 2 naal varaikkum vachukalaam.
A15: 4 | B15: Weekend-laye kaai-ellaam (beans, carrot, kovakkai, beetroot) narukki airtight box-la vachaa weekday poriyal 10 nimishathula mudinjidum.
A16: 5 | B16: Thinai, varagu, samai-va kaalaila 20 nimisham oora vachaa seekiram vegum. Tiffin pack pannum podhu thayir sadam-la thayir-a koncham kadaisila serunga, pulikkaama irukkum.
A18: Daily Wellness Habits
A19: 1 | B19: Thanneer: naalaikku 2.5–3 L. Saapadukku munnaadi 1 glass, mor-um count aagum.
A20: 2 | B20: Thookkam: 7–8 mani neram, oru fixed time-la thoongi ezhunga.
A21: 3 | B21: Nadai: saapitta piragu 10–15 nimisham nadakkunga. Mudhal 2 vaaram daily 4,000 steps, apparam medhuvaa 7,000–8,000 varaikkum ethunga.
A22: 4 | B22: Mindful eating: chinna thattu/katori use pannunga. Mobile/TV illaama, mella menu saapidunga. 80% vayiru nirainjaa podhum.
A23: 5 | B23: Coffee/tea: naalaikku maximum 2 tumbler, toned milk, sugar illama (illa ½ tsp kooda thaandaama). Biscuit side-la vendaam.
A24: 6 | B24: Weekly check: vaaram oru thadava ore naal, ore time-la weight paarunga, daily paakka vendaam.
A26: Important Note
A27: 1 | B27: Idhu general guidance mattum thaan, medical advice illa. Ungaloda BMI ~39.5 irukkaradhaala, aarambikkum munnaadi oru doctor kitta basic check-up (thyroid, sugar, BP, haemoglobin) pannunga. Unga udambukku etha maadhiri portion-a fine-tune panna oru registered dietitian-a consult pannunga.
