Workbook

Sheet ஆற்றல் இலக்கு
A1: தினசரி கலோரி இலக்கு (Mifflin-St Jeor)
A2: மஞ்சள் கட்டங்கள் உள்ளீடுகள். எதை மாற்றினாலும் எல்லா எண்களும் தானாக மாறும்.
A4: விவரம் | B4: மதிப்பு | C4: குறிப்பு
A5: வயது (ஆண்டுகள்) | B5: 40 | C5: உங்கள் விவரத்திலிருந்து
A6: உயரம் (செ.மீ) | B6: 155 | C6: "5.1" என்பதை 5 அடி 1 அங்குலம் ≈ 155 செ.மீ என எடுத்துக்கொண்டேன்
A7: தற்போதைய எடை (கி.கி) | B7: 95 | C7: உங்கள் விவரத்திலிருந்து
A8: இலக்கு எடை (கி.கி) | B8: 64 | C8: உங்கள் விவரத்திலிருந்து
A9: செயல்பாட்டுக் காரணி | B9: 1.2 | C9: அமர்ந்த நிலை = 1.2 (லேசான 1.375, மிதமான 1.55, அதிக 1.725)
A10: கலோரி குறைப்பு (kcal/நாள்) | B10: 470 | C10: மிதமான குறைப்பு, 300–500 வரம்புக்குள்
A11: புரதம் (இலக்கு எடைக்கு கி.கி-க்கு கிராம்) | B11: 1 | C11: பரிந்துரை வரம்பு 1.0–1.2
A12: குறைந்தபட்ச கலோரி (பெண்கள்) | B12: 1200 | C12: இதற்குக் கீழே போகக் கூடாது
A13: BMR (kcal/நாள்) | B13: =ROUND(10*B7+6.25*B6-5*B5-161,-1) -> 1560 | C13: 10×எடை + 6.25×உயரம் − 5×வயது − 161
A14: TDEE / பராமரிப்பு (kcal/நாள்) | B14: =ROUND(B13*B9,-1) -> 1870 | C14: BMR × செயல்பாட்டுக் காரணி
A15: தினசரி கலோரி இலக்கு (kcal/நாள்) | B15: =MAX(ROUND(B14-B10,-2),B12) -> 1400 | C15: TDEE − குறைப்பு, முழு எண்ணாக்கி, குறைந்தபட்சத்துக்கு மேல்
A16: தினசரி புரத இலக்கு (கிராம்) | B16: =ROUND(B8*B11,0) -> 64 | C16: இலக்கு எடை × கிராம்/கி.கி
A17: எதிர்பார்க்கும் குறைவு (கி.கி/வாரம்) | B17: =ROUND((B14-B15)*7/7700,2) -> 0.43 | C17: 1 கி.கி கொழுப்பு ≈ 7,700 kcal
A18: BMI (தற்போது) | B18: =ROUND(B7/(B6/100)^2,1) -> 39.5 | C18: எடை ÷ உயரம்² (மீ)

Sheet உணவுத் திட்டம்
A1: 7 நாள் தமிழ்நாடு சைவ உணவுத் திட்டம் (~1,400 kcal)
A2: கலோரி, புரதம் தோராயமான மதிப்பீடுகள். ஒவ்வொரு வேளைக்கும் ~1 டீஸ்பூன் எண்ணெய் (நாளுக்கு 3–4 டீஸ்பூன்). நாள் மொத்தம் தானாகக் கூட்டப்படும்.
A4: நாள் | B4: வேளை | C4: உணவு | D4: அளவு (வீட்டு அளவு) | E4: தோராய அளவு (கிராம்/மி.லி) | F4: தோராய kcal | G4: புரதம் (கிராம்)
A5: நாள் 1 (திங்கள்) | B5: காலை உணவு | C5: கேழ்வரகு தோசை + தக்காளி சட்னி + சாம்பார் + ஃபில்டர் காபி | D5: 2 நடுத்தர தோசை (ஒவ்வொன்றுக்கும் ½ டீஸ்பூன் எண்ணெய்), 2 டேபிள்ஸ்பூன் சட்னி, 1 கிண்ணம் சாம்பார், 1 டம்ளர் காபி | E5: 120 கி தோசை, 30 கி சட்னி, 150 மி.லி சாம்பார், 100 மி.லி காபி | F5: 390 | G5: 15
A6: நாள் 1 (திங்கள்) | B6: மதிய உணவு (டிஃபன்) | C6: முளைக்கீரை கூட்டு + சிவப்பு அரிசி சாதம் + பீன்ஸ் பொரியல் + தயிர் | D6: 1 கப் கூட்டு, ½ கப் சாதம், ½ கப் பொரியல், 1 கிண்ணம் தயிர் | E6: 200 கி கூட்டு, 75 கி சாதம், 75 கி பொரியல், 150 கி தயிர் | F6: 420 | G6: 18
A7: நாள் 1 (திங்கள்) | B7: மாலை சிற்றுண்டி | C7: கொண்டைக்கடலை சுண்டல் + கொய்யாப்பழம் | D7: ½ கப் சுண்டல், 1 நடுத்தர கொய்யா | E7: 80 கி சுண்டல், 150 கி கொய்யா | F7: 210 | G7: 9
A8: நாள் 1 (திங்கள்) | B8: இரவு உணவு | C8: சப்பாத்தி + பனீர் பட்டாணி குருமா + வெள்ளரிக்காய் சாலட் | D8: 2 சப்பாத்தி (நெய் இல்லாமல்), ½ கப் குருமா, 1 சிறிய தட்டு சாலட் | E8: 60 கி மாவு, 150 மி.லி குருமாவில் 60 கி பனீர், 80 கி வெள்ளரி | F8: 440 | G8: 20
A9: நாள் 1 (திங்கள்) | B9: நாள் மொத்தம் | F9: =SUM(F5:F8) -> 1460 | G9: =SUM(G5:G8) -> 62
A10: நாள் 2 (செவ்வாய்) | B10: காலை உணவு | C10: பெசரட்டு + இஞ்சி சட்னி + ஃபில்டர் காபி | D10: 2 நடுத்தர பெசரட்டு, 2 டேபிள்ஸ்பூன் சட்னி, 1 டம்ளர் காபி | E10: 160 கி மாவு, 30 கி சட்னி, 100 மி.லி காபி | F10: 350 | G10: 18
A11: நாள் 2 (செவ்வாய்) | B11: மதிய உணவு (டிஃபன்) | C11: தினை சாம்பார் சாதம் + வெள்ளரிக்காய் தயிர் பச்சடி + நீர் மோர் | D11: 1½ கப் சாம்பார் சாதம், ½ கப் பச்சடி, 1 கிளாஸ் மோர் | E11: 300 கி, 100 கி, 200 மி.லி | F11: 490 | G11: 19
A12: நாள் 2 (செவ்வாய்) | B12: மாலை சிற்றுண்டி | C12: பச்சைப் பயறு சுண்டல் + ஆரஞ்சு | D12: ¾ கப் சுண்டல், 1 ஆரஞ்சு | E12: 120 கி, 130 கி | F12: 190 | G12: 10
A13: நாள் 2 (செவ்வாய்) | B13: இரவு உணவு | C13: முருங்கைக்கீரை அடை + அவியல் | D13: 2 நடுத்தர அடை (மொத்தம் 1 டீஸ்பூன் எண்ணெய்), ½ கப் அவியல் | E13: 180 கி மாவு, 100 கி அவியல் | F13: 410 | G13: 15
A14: நாள் 2 (செவ்வாய்) | B14: நாள் மொத்தம் | F14: =SUM(F10:F13) -> 1440 | G14: =SUM(G10:G13) -> 62
A15: நாள் 3 (புதன்) | B15: காலை உணவு | C15: இட்லி + சாம்பார் + புதினா சட்னி + ஃபில்டர் காபி | D15: 3 நடுத்தர இட்லி, 1 கிண்ணம் சாம்பார், 2 டேபிள்ஸ்பூன் சட்னி, 1 டம்ளர் காபி | E15: 150 கி இட்லி, 150 மி.லி சாம்பார், 30 கி சட்னி, 100 மி.லி காபி | F15: 380 | G15: 16
A16: நாள் 3 (புதன்) | B16: மதிய உணவு (டிஃபன்) | C16: கம்பு சாதம் + கத்திரிக்காய் பருப்பு கூட்டு + கேரட் பொரியல் + தயிர் | D16: ½ கப் கம்பு சாதம், 1 கப் கூட்டு, ½ கப் பொரியல், ½ கிண்ணம் தயிர் | E16: 80 கி, 200 கி, 75 கி, 100 கி | F16: 390 | G16: 15
A17: நாள் 3 (புதன்) | B17: மாலை சிற்றுண்டி | C17: வேகவைத்த வேர்க்கடலை சுண்டல் + பப்பாளி | D17: ⅓ கப் சுண்டல், 1 கப் பப்பாளித் துண்டுகள் | E17: 50 கி, 150 கி | F17: 200 | G17: 8
A18: நாள் 3 (புதன்) | B18: இரவு உணவு | C18: சப்பாத்தி + பாலக் பனீர் (கீரை பனீர்) + வெங்காய சாலட் | D18: 2 சப்பாத்தி, ½ கப் கீரை பனீர், சிறிய தட்டு சாலட் | E18: 60 கி மாவு, 75 கி பனீர் + 100 கி பாலக், 60 கி சாலட் | F18: 450 | G18: 22
A19: நாள் 3 (புதன்) | B19: நாள் மொத்தம் | F19: =SUM(F15:F18) -> 1420 | G19: =SUM(G15:G18) -> 61
A20: நாள் 4 (வியாழன்) | B20: காலை உணவு | C20: சாமை பொங்கல் + தக்காளி சட்னி + சாம்பார் + ஃபில்டர் காபி | D20: ¾ கப் பொங்கல் (½ டீஸ்பூன் நெய்), 2 டேபிள்ஸ்பூன் சட்னி, ½ கிண்ணம் சாம்பார், 1 டம்ளர் காபி | E20: 180 கி பொங்கல், 30 கி சட்னி, 75 மி.லி சாம்பார், 100 மி.லி காபி | F20: 390 | G20: 15
A21: நாள் 4 (வியாழன்) | B21: மதிய உணவு (டிஃபன்) | C21: தக்காளி பருப்பு + சிவப்பு அரிசி சாதம் + கோவைக்காய் பொரியல் + தயிர் | D21: 1 பெரிய கிண்ணம் பருப்பு, ½ கப் சாதம், ½ கப் பொரியல், 1 கிண்ணம் தயிர் | E21: 200 மி.லி, 75 கி, 75 கி, 150 கி | F21: 430 | G21: 18
A22: நாள் 4 (வியாழன்) | B22: மாலை சிற்றுண்டி | C22: காராமணி சுண்டல் + ஆப்பிள் | D22: ½ கப் சுண்டல், 1 சிறிய ஆப்பிள் | E22: 80 கி, 130 கி | F22: 190 | G22: 7
A23: நாள் 4 (வியாழன்) | B23: இரவு உணவு | C23: கேழ்வரகு இடியாப்பம் + பனீர் காய்கறி குருமா + முருங்கைக்கீரை பொரியல் | D23: 2 இடியாப்பம், 1 கிண்ணம் குருமா, ¼ கப் பொரியல் | E23: 80 கி, 150 மி.லி குருமாவில் 75 கி பனீர், 50 கி பொரியல் | F23: 410 | G23: 20
A24: நாள் 4 (வியாழன்) | B24: நாள் மொத்தம் | F24: =SUM(F20:F23) -> 1420 | G24: =SUM(G20:G23) -> 60
A25: நாள் 5 (வெள்ளி) | B25: காலை உணவு | C25: காய்கறி குழிப்பணியாரம் + சாம்பார் + ஃபில்டர் காபி | D25: 5 சிறிய பணியாரம் (1 டீஸ்பூன் எண்ணெய்), 1 கிண்ணம் சாம்பார், 1 டம்ளர் காபி | E25: 125 கி, 150 மி.லி, 100 மி.லி | F25: 360 | G25: 14
A26: நாள் 5 (வெள்ளி) | B26: மதிய உணவு (டிஃபன்) | C26: வரகு தயிர் சாதம் (வெள்ளரிக்காயுடன்) + பாசிப்பருப்பு கோசம்பரி + பீட்ரூட்-கேரட் சாலட் | D26: 1½ கப் தயிர் சாதம், ½ கப் கோசம்பரி, ½ கப் சாலட் | E26: 300 கி (200 கி தயிருடன்), 60 கி, 80 கி | F26: 430 | G26: 17
A27: நாள் 5 (வெள்ளி) | B27: மாலை சிற்றுண்டி | C27: முளைகட்டிய பயறு சாலட் + பொட்டுக்கடலை + பப்பாளி | D27: 1 கப் முளைப்பயறு, 1 டேபிள்ஸ்பூன் பொட்டுக்கடலை, 1 கப் பப்பாளி | E27: 100 கி, 15 கி, 150 கி | F27: 210 | G27: 10
A28: நாள் 5 (வெள்ளி) | B28: இரவு உணவு | C28: சப்பாத்தி + பச்சைப் பயறு குழம்பு + வெங்காய-வெள்ளரி சாலட் | D28: 2 சப்பாத்தி, 1 பெரிய கிண்ணம் குழம்பு, சிறிய தட்டு சாலட் | E28: 60 கி மாவு, 200 மி.லி, 60 கி | F28: 440 | G28: 20
A29: நாள் 5 (வெள்ளி) | B29: நாள் மொத்தம் | F29: =SUM(F25:F28) -> 1440 | G29: =SUM(G25:G28) -> 61
A30: நாள் 6 (சனி) | B30: காலை உணவு | C30: தினை காய்கறி உப்புமா + தேங்காய்-பொட்டுக்கடலை சட்னி + ஃபில்டர் காபி | D30: ¾ கப் உப்புமா, 2 டேபிள்ஸ்பூன் சட்னி, 1 டம்ளர் காபி | E30: 150 கி, 30 கி, 100 மி.லி | F30: 330 | G30: 11
A31: நாள் 6 (சனி) | B31: மதிய உணவு (வீட்டில்) | C31: முருங்கைக்காய் சாம்பார் + சிவப்பு அரிசி சாதம் + அவியல் + ரசம் + தயிர் | D31: 1 பெரிய கிண்ணம் சாம்பார், ½ கப் சாதம், ½ கப் அவியல், 1 சிறிய கிண்ணம் ரசம், ½ கிண்ணம் தயிர் | E31: 200 மி.லி, 75 கி, 100 கி, 100 மி.லி, 100 கி | F31: 450 | G31: 17
A32: நாள் 6 (சனி) | B32: மாலை சிற்றுண்டி | C32: வேர்க்கடலை சுண்டல் + மசாலா மோர் | D32: ⅓ கப் சுண்டல், 1 கிளாஸ் மோர் | E32: 50 கி, 200 மி.லி | F32: 180 | G32: 9
A33: நாள் 6 (சனி) | B33: இரவு உணவு | C33: கோதுமை தோசை + செட்டிநாடு பனீர் மசாலா | D33: 2 தோசை (மொத்தம் 1 டீஸ்பூன் எண்ணெய்), ½ கப் மசாலா | E33: 70 கி மாவு, 120 மி.லி கிரேவியில் 75 கி பனீர் | F33: 470 | G33: 21
A34: நாள் 6 (சனி) | B34: நாள் மொத்தம் | F34: =SUM(F30:F33) -> 1430 | G34: =SUM(G30:G33) -> 58
A35: நாள் 7 (ஞாயிறு) | B35: காலை உணவு | C35: இட்லி + மெது வடை (வாரத்துக்கு ஒரு முறை ட்ரீட், 1 சிறியது) + சாம்பார் + தேங்காய் சட்னி + ஃபில்டர் காபி | D35: 3 நடுத்தர இட்லி, 1 சிறிய வடை, 1 கிண்ணம் சாம்பார், 2 டேபிள்ஸ்பூன் சட்னி, 1 டம்ளர் காபி | E35: 150 கி, 40 கி, 150 மி.லி, 30 கி, 100 மி.லி | F35: 520 | G35: 20
A36: நாள் 7 (ஞாயிறு) | B36: மதிய உணவு (வீட்டில்) | C36: மோர்க்குழம்பு + சிவப்பு அரிசி சாதம் + பீன்ஸ் பருப்பு உசிலி + பசலைக்கீரை பொரியல் + ரசம் | D36: 1 கிண்ணம் குழம்பு, ½ கப் சாதம், ½ கப் உசிலி, ¼ கப் பொரியல், 1 சிறிய கிண்ணம் ரசம் | E36: 150 மி.லி, 75 கி, 100 கி, 50 கி, 100 மி.லி | F36: 440 | G36: 16
A37: நாள் 7 (ஞாயிறு) | B37: மாலை சிற்றுண்டி | C37: பச்சைப் பயறு சுண்டல் + ஆரஞ்சு | D37: ¾ கப் சுண்டல், 1 ஆரஞ்சு | E37: 120 கி, 130 கி | F37: 190 | G37: 10
A38: நாள் 7 (ஞாயிறு) | B38: இரவு உணவு | C38: பாசிப்பருப்பு காய்கறி கிச்சடி + வெள்ளரிக்காய் ரைத்தா | D38: 1 கப் கிச்சடி, ½ கப் ரைத்தா | E38: 200 கி, 100 கி | F38: 310 | G38: 13
A39: நாள் 7 (ஞாயிறு) | B39: நாள் மொத்தம் | F39: =SUM(F35:F38) -> 1460 | G39: =SUM(G35:G38) -> 59
E40: வார சராசரி / நாள் | F40: =ROUND(AVERAGE(F9,F14,F19,F24,F29,F34,F39),0) -> 1439 | G40: =ROUND(AVERAGE(G9,G14,G19,G24,G29,G34,G39),0) -> 60
E41: இலக்கு (ஆற்றல் இலக்கிலிருந்து) | F41: ='ஆற்றல் இலக்கு'!B15 -> 1400 | G41: ='ஆற்றல் இலக்கு'!B16 -> 64
...

Sheet வார சுருக்கம்
A1: வார சுருக்கம்
A2: மொத்தங்கள் உணவுத் திட்டத் தாளிலிருந்து இணைக்கப்பட்டுள்ளன (பச்சை).
A4: நாள் | B4: மொத்த kcal | C4: மொத்த புரதம் (கிராம்) | D4: இலக்கிலிருந்து வேறுபாடு | E4: பயன்படுத்திய சிறுதானியம்/முழு தானியம் | F4: பயன்படுத்திய கீரை/காய்கறிகள்
A5: நாள் 1 (திங்கள்) | B5: ='உணவுத் திட்டம்'!F9 -> 1460 | C5: ='உணவுத் திட்டம்'!G9 -> 62 | D5: =B5-'ஆற்றல் இலக்கு'!$B$15 -> 60 | E5: கேழ்வரகு, சிவப்பு அரிசி, கோதுமை | F5: முளைக்கீரை, பீன்ஸ், வெள்ளரி, பட்டாணி
A6: நாள் 2 (செவ்வாய்) | B6: ='உணவுத் திட்டம்'!F14 -> 1440 | C6: ='உணவுத் திட்டம்'!G14 -> 62 | D6: =B6-'ஆற்றல் இலக்கு'!$B$15 -> 40 | E6: தினை | F6: முருங்கைக்கீரை, அவியல் காய்கறிகள், வெள்ளரி
A7: நாள் 3 (புதன்) | B7: ='உணவுத் திட்டம்'!F19 -> 1420 | C7: ='உணவுத் திட்டம்'!G19 -> 61 | D7: =B7-'ஆற்றல் இலக்கு'!$B$15 -> 20 | E7: கம்பு, கோதுமை | F7: பாலக், கத்திரிக்காய், கேரட்
A8: நாள் 4 (வியாழன்) | B8: ='உணவுத் திட்டம்'!F24 -> 1420 | C8: ='உணவுத் திட்டம்'!G24 -> 60 | D8: =B8-'ஆற்றல் இலக்கு'!$B$15 -> 20 | E8: சாமை, கேழ்வரகு, சிவப்பு அரிசி | F8: முருங்கைக்கீரை, கோவைக்காய், தக்காளி
A9: நாள் 5 (வெள்ளி) | B9: ='உணவுத் திட்டம்'!F29 -> 1440 | C9: ='உணவுத் திட்டம்'!G29 -> 61 | D9: =B9-'ஆற்றல் இலக்கு'!$B$15 -> 40 | E9: வரகு, கோதுமை | F9: பீட்ரூட், கேரட், வெள்ளரி
A10: நாள் 6 (சனி) | B10: ='உணவுத் திட்டம்'!F34 -> 1430 | C10: ='உணவுத் திட்டம்'!G34 -> 58 | D10: =B10-'ஆற்றல் இலக்கு'!$B$15 -> 30 | E10: தினை, சிவப்பு அரிசி | F10: முருங்கைக்காய், அவியல் காய்கறிகள்
A11: நாள் 7 (ஞாயிறு) | B11: ='உணவுத் திட்டம்'!F39 -> 1460 | C11: ='உணவுத் திட்டம்'!G39 -> 59 | D11: =B11-'ஆற்றல் இலக்கு'!$B$15 -> 60 | E11: சிவப்பு அரிசி | F11: பசலைக்கீரை, பீன்ஸ், வெள்ளரி
A12: சராசரி | B12: =ROUND(AVERAGE(B5:B11),0) -> 1439 | C12: =ROUND(AVERAGE(C5:C11),0) -> 60
A14: குறிப்பு: புரதம் சராசரியாக ~60 கிராம், 65 கிராம் இலக்கை விட சற்றுக் குறைவு. தினமும் கூடுதலாக 1 கிண்ணம் தயிர் அல்லது 1 கிளாஸ் மோர் (~50 kcal) சேர்த்தால் இலக்கை எட்டலாம்.

Sheet மளிகைப் பட்டியல்
A1: இந்த வாரத்துக்கான மளிகைப் பட்டியல் (1 நபர்)
A2: வாங்கியதும் "வாங்கியது?" கட்டத்தில் ✓ போடுங்கள்.
A4: வகை | B4: பொருள் | C4: தோராய அளவு | D4: வாங்கியது?
A5: தானியங்கள் & சிறுதானியங்கள் | B5: கேழ்வரகு மாவு | C5: 250 கி
A6: தானியங்கள் & சிறுதானியங்கள் | B6: தினை | C6: 400 கி
A7: தானியங்கள் & சிறுதானியங்கள் | B7: கம்பு | C7: 150 கி
A8: தானியங்கள் & சிறுதானியங்கள் | B8: சாமை | C8: 200 கி
A9: தானியங்கள் & சிறுதானியங்கள் | B9: வரகு | C9: 200 கி
A10: தானியங்கள் & சிறுதானியங்கள் | B10: சிவப்பு அரிசி | C10: 500 கி
A11: தானியங்கள் & சிறுதானியங்கள் | B11: இட்லி/தோசை மாவு (அல்லது இட்லி அரிசி 400 கி + உளுந்து 100 கி) | C11: 1 கி.கி
A12: தானியங்கள் & சிறுதானியங்கள் | B12: கோதுமை மாவு | C12: 500 கி
A13: தானியங்கள் & சிறுதானியங்கள் | B13: புழுங்கல் அரிசி (அடைக்கு) | C13: 100 கி
A14: பருப்பு வகைகள் | B14: துவரம் பருப்பு | C14: 300 கி
A15: பருப்பு வகைகள் | B15: பாசிப்பருப்பு | C15: 300 கி
A16: பருப்பு வகைகள் | B16: பச்சைப் பயறு (முழு) | C16: 500 கி
... A56: மசாலா & இதர பொருட்கள் | B56: உப்பு | C56: தேவையான அளவு

Sheet மாற்றுகள் & குறிப்புகள்
A1: மாற்றுகள், முன்கூட்டிய தயாரிப்பு & தினசரி பழக்கங்கள்
A3: எளிய மாற்றுகள்
A4: 1 | B4: தினை ↔ சாமை ↔ வரகு: ஒரே மாதிரி சமைக்கலாம், கிடைப்பதைப் பயன்படுத்துங்கள்.
A5: 2 | B5: பனீர் ↔ கெட்டித் தயிர் (hung curd): கிரேவியில் கடைசியாகச் சேருங்கள், கொதிக்க விடாதீர்கள்.
A6: 3 | B6: முருங்கைக்கீரை ↔ முளைக்கீரை ↔ சிறுகீரை: அடை, பொரியல், கூட்டு எல்லாவற்றுக்கும் மாற்றலாம்.
A7: 4 | B7: கொண்டைக்கடலை ↔ காராமணி ↔ மொச்சை: சுண்டலுக்கு அதே அளவு.
A8: 5 | B8: சிவப்பு அரிசி ↔ கைக்குத்தல் அரிசி ↔ ½ பொன்னி + ½ தினை: அளவு ½ கப் மட்டுமே.
A9: 6 | B9: பப்பாளி ↔ கொய்யா ↔ ஆரஞ்சு: பருவத்தில் மலிவாகக் கிடைப்பதை வாங்குங்கள்.
A11: முன்கூட்டிய தயாரிப்பு குறிப்புகள்
A12: 1 | B12: ஞாயிறு மற்றும் புதன் அன்று இட்லி/தோசை மாவு அரைத்து வைத்துக்கொள்ளுங்கள். கேழ்வரகு தோசைக்கு அதில் கேழ்வரகு மாவு கலக்கலாம்.
A13: 2 | B13: தூங்கப் போகும் முன், அடுத்த நாள் சுண்டலுக்கு கொண்டைக்கடலை/காராமணி/பச்சைப் பயறு ஊற வையுங்கள். முளைப்பயறுக்கு 2 நாள் முன்பே ஊற வையுங்கள்.
A14: 3 | B14: சாம்பார், பருப்பு இரண்டு வேளைக்குச் சேர்த்துச் செய்யுங்கள் (காலை சாம்பார் மதியத்துக்கும், குழம்பு இரவுக்கும்). ஃப்ரிட்ஜில் 2 நாள் வரை வைக்கலாம்.
A15: 4 | B15: வார இறுதியிலேயே காய்கறிகளை (பீன்ஸ், கேரட், கோவைக்காய், பீட்ரூட்) நறுக்கி காற்றுப் புகாத டப்பாவில் வைத்தால் வார நாள் பொரியல் 10 நிமிடத்தில் முடியும்.
A16: 5 | B16: தினை, வரகு, சாமையை காலையில் 20 நிமிடம் ஊற வைத்தால் சீக்கிரம் வேகும். டிஃபன் தயிர் சாதத்தில் தயிரைக் கடைசியாகச் சேர்த்தால் புளிக்காது.
A18: தினசரி நலப் பழக்கங்கள்
A19: 1 | B19: தண்ணீர்: நாளுக்கு 2.5–3 லிட்டர். ஒவ்வொரு உணவுக்கு முன் 1 கிளாஸ்; மோரும் கணக்கில் சேரும்.
A20: 2 | B20: தூக்கம்: 7–8 மணி நேரம், ஒரே நேரத்தில் தூங்கி எழுங்கள்.
A21: 3 | B21: நடை: சாப்பிட்ட பிறகு 10–15 நிமிடம் நடங்கள். முதல் 2 வாரம் தினமும் 4,000 அடிகள், பிறகு மெதுவாக 7,000–8,000 வரை உயர்த்துங்கள்.
A22: 4 | B22: கவனத்துடன் சாப்பிடுதல்: சிறிய தட்டு/கிண்ணம் பயன்படுத்துங்கள். மொபைல்/டிவி இல்லாமல் மெதுவாகச் சாப்பிடுங்கள். 80% வயிறு நிறைந்தால் போதும்.
A23: 5 | B23: காபி/டீ: நாளுக்கு அதிகபட்சம் 2 டம்ளர், டோன்ட் பால், சர்க்கரை இல்லாமல் (அல்லது ½ டீஸ்பூனுக்கு மேல் வேண்டாம்). பிஸ்கட் வேண்டாம்.
A24: 6 | B24: வாராந்திர சரிபார்ப்பு: வாரம் ஒருமுறை ஒரே நாள், ஒரே நேரத்தில் எடை பாருங்கள்; தினமும் பார்க்க வேண்டாம்.
A26: முக்கியக் குறிப்பு
A27: 1 | B27: இது பொதுவான வழிகாட்டுதல் மட்டுமே, மருத்துவ ஆலோசனை அல்ல. உங்கள் BMI சுமார் 39.5 என்பதால், தொடங்குவதற்கு முன் மருத்துவரிடம் அடிப்படைப் பரிசோதனை (தைராய்டு, சர்க்கரை, இரத்த அழுத்தம், ஹீமோகுளோபின்) செய்துகொள்ளுங்கள். உங்கள் உடலுக்கு ஏற்ற அளவுகளைச் சரிசெய்ய பதிவுபெற்ற உணவியல் நிபுணரை அணுகுங்கள்.
